Workbook

Sheet Computation performance
A1: Time in seconds to execute 2 x 10^8 operations of a certain type (measurement 1) | H1: Time in seconds to execute 2 x 10^8 operations of a certain type (measurement 2)
C2: Short | D2: Integer | E2: Float | F2: Double | J2: Short | K2: Integer | L2: Float | M2: Double
C3: Type1 | D3: Type2 | E3: Type3 | F3: Type4 | J3: Type1 | K3: Type2 | L3: Type3 | M3: Type4
A4: Odroid01 | B4: P1 | C4: ='RAW All cores per device'!C3 -> 0.7382963 | D4: ='RAW All cores per device'!D3 -> 0.555614 | E4: ='RAW All cores per device'!E3 -> 0.7363863 | F4: ='RAW All cores per device'!F3 -> 0.7361596 | H4: Odroid01 | I4: P0 | J4: 0.721741 | K4: 0.5298765 | L4: 0.7957048 | M4: 0.7950559
A5: Odroid02 | B5: P2 | C5: ='RAW All cores per device'!C7 -> 0.8048089 | D5: ='RAW All cores per device'!D7 -> 0.6854336 | E5: ='RAW All cores per device'!E7 -> 1.1257956 | F5: ='RAW All cores per device'!F7 -> 0.8855114 | H5: Odroid01 | I5: P1 | J5: 0.7220023 | K5: 0.5297623 | L5: 0.7950549 | M5: 0.7946115
A6: Odroid03 | B6: P3 | C6: ='RAW All cores per device'!C11 -> 0.8325372 | D6: ='RAW All cores per device'!D11 -> 0.7277727 | E6: ='RAW All cores per device'!E11 -> 0.7956429 | F6: ='RAW All cores per device'!F11 -> 1.080889 | H6: Odroid01 | I6: P2 | J6: 0.728555 | K6: 0.5306499 | L6: 0.798737 | M6: 0.7960896
A7: Odroid04 | B7: P4 | C7: ='RAW All cores per device'!C15 -> 0.6796339 | D7: ='RAW All cores per device'!D15 -> 0.5584648 | E7: ='RAW All cores per device'!E15 -> 0.7357173 | F7: ='RAW All cores per device'!F15 -> 0.7361138 | H7: Odroid01 | I7: P3 | J7: 0.7212231 | K7: 0.5295181 | L7: 0.7943854 | M7: 0.7941089
A8: Odroid05 | B8: P5 | C8: 0.6819882 | D8: 0.5584373 | E8: 0.7355192 | F8: 0.735532 | H8: Odroid02 | I8: P4 | J8: 0.8435464 | K8: 0.52964 | L8: 0.7942967 | M8: 0.9773958
A9: Cubie01 | B9: P6 | C9: 3.6219628 | D9: 3.1862373 | E9: 2.8632758 | F9: 2.7685792 | H9: Odroid02 | I9: P5 | J9: 0.720643 | K9: 0.7345903 | L9: 1.129277 | M9: 0.9142442
A10: Cubie02 | B10: P7 | C10: 3.4532492 | D10: 3.2484446 | E10: 2.7866964 | F10: 2.9172852 | H10: Odroid02 | I10: P6 | J10: 0.8014898 | K10: 0.5296478 | L10: 1.089535 | M10: 1.0330136
A11: Odroid01 | B11: P8 | C11: 0.7461092 | D11: 0.5556548 | E11: 0.736021 | F11: 0.7361999 | H11: Odroid02 | I11: P7 | J11: 1.0781105 | K11: 0.6295507 | L11: 0.8541739 | M11: 1.0150619
A12: Odroid02 | B12: P9 | C12: 0.8545518 | D12: 0.5500474 | E12: 1.0103087 | F12: 0.8953927 | H12: Odroid03 | I12: P8 | J12: 0.78565 | K12: 0.6646938 | L12: 0.8347814 | M12: 0.8444624
A13: Odroid03 | B13: P10 | C13: 1.0882497 | D13: 0.8917489 | E13: 0.9838085 | F13: 0.7662902 | H13: Odroid03 | I13: P9 | J13: 0.8426712 | K13: 0.5894914 | L13: 1.125983 | M13: 1.0044503
A14: Odroid04 | B14: P11 | C14: 0.7335615 | D14: 0.5450363 | E14: 0.7351909 | F14: 0.7352724 | H14: Odroid03 | I14: P10 | J14: 1.270885 | K14: 0.5497081 | L14: 1.0872288 | M14: 0.9843795
A15: Odroid05 | B15: P12 | C15: 0.7351615 | D15: 0.550807 | E15: 0.7352698 | F15: 0.7353961 | H15: Odroid03 | I15: P11 | J15: 0.8512347 | K15: 0.5594728 | L15: 1.1648452 | M15: 1.1492805
A16: Cubie01 | B16: P13 | C16: 1.78982 | D16: 1.5902929 | E16: 1.7891579 | F16: 1.9685693 | H16: Odroid04 | I16: P12 | J16: 0.7507296 | K16: 0.7595346 | L16: 0.9141924 | M16: 1.0142369
A17: Cubie02 | B17: P14 | C17: 3.6433318 | D17: 3.2263098 | E17: 2.9380882 | F17: 2.671077 | H17: Odroid04 | I17: P13 | J17: 1.2157755 | K17: 0.5295236 | L17: 0.7941375 | M17: 0.794142
A18: Odroid01 | B18: P15 | C18: 0.7352505 | D18: 0.5524387 | E18: 0.7368162 | F18: 0.7370129 | H18: Odroid04 | I18: P14 | J18: 0.8440938 | K18: 0.6144574 | L18: 1.2373736 | M18: 1.2295153
A19: Odroid02 | B19: P16 | C19: 0.8625188 | D19: 0.5910425 | E19: 1.1066883 | F19: 1.1262484 | H19: Odroid04 | I19: P15 | J19: 0.8151562 | K19: 0.8497162 | L19: 1.3463459 | M19: 0.9393737
... A27: Odroid03 | B27: P24 | C27: 0.7634528 | D27: 0.5966537 | E27: 1.1051726 | F27: 1.0166357 | H27: Cubie02 | I27: P23 | J27: 2.0845342 | K27: 2.2934287 | L27: 3.5805948 | M27: 2.6235089
H28: Raspi01 | I28: P24 | J28: 3.5120053 | K28: 2.9329429 | L28: 5.6131094 | M28: 5.5673122
H29: Raspi02 | I29: P25 | J29: 3.4880276 | K29: 2.909606 | L29: 5.5222883 | M29: 5.5234995
A30: Single core per device
A32: Odroid01 | B32: P1 | C32: 0.71772 | D32: 0.5540404 | E32: 0.7353783 | F32: 0.7354515
A33: Odroid02 | B33: P2 | C33: 0.7346902 | D33: 0.5542085 | E33: 0.7351716 | F33: 0.7352653
A34: Odroid03 | B34: P3 | C34: 0.7351234 | D34: 0.5539336 | E34: 0.7356129 | F34: 0.7358246
A35: Odroid04 | B35: P4 | C35: 0.6795611 | D35: 0.5588586 | E35: 0.7356608 | F35: 0.7356374
A36: Odroid05 | B36: P5 | C36: 0.7337229 | D36: 0.5491896 | E36: 0.7355223 | F36: 0.7364063
A37: Cubie01 | B37: P6 | C37: 1.8010941 | D37: 1.59076 | E37: 1.788518 | F37: 1.7885957
A38: Cubie02 | B38: P7 | C38: 1.8004255 | D38: 1.5899639 | E38: 1.7885997 | F38: 1.7885766

Sheet Average comm performance
A1: Time in seconds to transfer 2621440 integers (should equivalent to 10MB of data), the bandwidth is 1/time
C2: Odroid01 | D2: Odroid02 | E2: Odroid03 | F2: Odroid04 | G2: Odroid05 | H2: Cubie01 | I2: Cubie02 | J2: Odroid01 | K2: Odroid02 | L2: Odroid03 | M2: Odroid04 | N2: Odroid05 | O2: Cubie01 | P2: Cubie02 | Q2: Odroid01 | R2: Odroid02 | S2: Odroid03 | T2: Odroid04 | U2: Odroid05 | V2: Cubie01 | W2: Cubie02 | X2: Odroid01 | Y2: Odroid02 | Z2: Odroid03
C3: P1 | D3: P2 | E3: P3 | F3: P4 | G3: P5 | H3: P6 | I3: P7 | J3: P8 | K3: P9 | L3: P10 | M3: P11 | N3: P12 | O3: P13 | P3: P14 | Q3: P15 | R3: P16 | S3: P17 | T3: P18 | U3: P19 | V3: P20 | W3: P21 | X3: P22 | Y3: P23 | Z3: P24
A4: Odroid01 | B4: P1 | C4: 0 | D4: 0.89180935 | E4: 0.88439595 | F4: 0.8862178 | G4: 0.8856912 | H4: 0.9448893 | I4: 0.93698885 | J4: 0.01842165 | K4: 0.93143915 | L4: 0.89611755 | M4: 0.8871461 | N4: 0.8883103 | O4: 1.010152 | P4: 0.98755135 | Q4: 0.0182102 | R4: 0.9021006 | S4: 0.90741505 | T4: 0.88714215 | U4: 0.88715385 | V4: 0.92385435 | W4: 0.9912934 | X4: 0.0183289 | Y4: 0.9367789 | Z4: 0.8890325
A5: Odroid02 | B5: P2 | C5: 0.88810335 | D5: 0 | E5: 0.9525244 | F5: 0.91815065 | G5: 0.8876456 | H5: 1.0237652 | I5: 0.9199467 | J5: 0.9389514 | K5: 0.0280367 | L5: 0.9367845 | M5: 0.92932225 | N5: 0.89941775 | O5: 0.9896896 | P5: 1.0685862 | Q5: 0.887514 | R5: 0.01838245 | S5: 0.9760023 | T5: 0.9166535 | U5: 0.88857505 | V5: 0.9384724 | W5: 1.1293179 | X5: 0.8983003 | Y5: 0.028399 | Z5: 0.9410517
A6: Odroid03 | B6: P3 | C6: 0.8863863 | D6: 0.95968615 | E6: 0 | F6: 0.9335322 | G6: 0.90662655 | H6: 0.93413445 | I6: 0.88423135 | J6: 0.89769245 | K6: 0.93710135 | L6: 0.02436505 | M6: 0.88828775 | N6: 0.9245777 | O6: 1.0073817 | P6: 0.9856963 | Q6: 0.8898246 | R6: 0.9139427 | S6: 0.0367707 | T6: 0.89183995 | U6: 0.89769195 | V6: 0.9682288 | W6: 1.071393 | X6: 0.89535785 | Y6: 0.9434824 | Z6: 0.04332675
A7: Odroid04 | B7: P4 | C7: 0.8881959 | D7: 0.91774105 | E7: 0.92778765 | F7: 0 | G7: 0.8898026 | H7: 0.9790553 | I7: 0.88416995 | J7: 0.88494955 | K7: 0.9263971 | L7: 0.9293698 | M7: 0.01854 | N7: 0.88881205 | O7: 0.9985132 | P7: 1.0138978 | Q7: 0.8850452 | R7: 0.93929935 | S7: 0.9022652 | T7: 0.01849435 | U7: 0.8886429 | V7: 0.8863233 | W7: 1.0031178 | X7: 0.884995 | Y7: 0.93522775 | Z7: 0.91586675
A8: Odroid05 | B8: P5 | C8: 0.88411345 | D8: 0.88887085 | E8: 0.90463695 | F8: 0.8855088 | G8: 0 | H8: 1.0041201 | I8: 0.8842932 | J8: 0.8848182 | K8: 0.91532685 | L8: 0.9106401 | M8: 0.8882784 | N8: 0.01863065 | O8: 0.9910023 | P8: 0.98038575 | Q8: 0.88499725 | R8: 0.92822005 | S8: 0.92940605 | T8: 0.88863255 | U8: 0.0187223 | V8: 0.8887845 | W8: 0.96640135 | X8: 0.8850416 | Y8: 0.92356195 | Z8: 0.9064008
A9: Cubie01 | B9: P6 | C9: 0.9472015 | D9: 1.0241995 | E9: 0.94115185 | F9: 0.98078545 | G9: 1.00604 | H9: 0 | I9: 1.0806655 | J9: 1.0725077 | K9: 1.0336696 | L9: 1.0713926 | M9: 0.97197375 | N9: 1.0461886 | O9: 0.98836865 | P9: 1.1383227 | Q9: 1.005256 | R9: 1.0551246 | S9: 1.0182022 | T9: 1.0157825 | U9: 1.0047865 | V9: 0.07781045 | W9: 1.0689049 | X9: 0.97481915 | Y9: 1.1020968 | Z9: 1.0244296
A10: Cubie02 | B10: P7 | C10: 0.93647765 | D10: 0.92118845 | E10: 0.8872825 | F10: 0.88735415 | G10: 0.8866167 | H10: 1.0770171 | I10: 0 | J10: 0.8875339 | K10: 0.90560805 | L10: 0.91311215 | M10: 0.88816605 | N10: 0.8866446 | O10: 1.0093195 | P10: 0.07795325 | Q10: 0.88557295 | R10: 0.9231844 | S10: 0.8901187 | T10: 0.8879725 | U10: 0.8879447 | V10: 0.8891854 | W10: 0.0749581 | X10: 0.88574445 | Y10: 0.92783785 | Z10: 0.8944156
A11: Odroid01 | B11: P8 | C11: 0.0186688 | D11: 0.93799855 | E11: 0.89784135 | F11: 0.88722875 | G11: 0.8866926 | H11: 1.0666434 | I11: 0.88409375 | J11: 0 | K11: 0.9318596 | L11: 0.92928645 | M11: 0.8866961 | N11: 0.88748685 | O11: 0.9878031 | P11: 0.9849744 | Q11: 0.0190058 | R11: 0.9460137 | S11: 0.91073145 | T11: 0.8874878 | U11: 0.8873489 | V11: 0.88799905 | W11: 0.9732847 | X11: 0.01886355 | Y11: 0.90045365 | Z11: 0.8988476
A12: Odroid02 | B12: P9 | C12: 0.9263893 | D12: 0.0280099 | E12: 0.9400555 | F12: 0.92254665 | G12: 0.91343215 | H12: 1.0322994 | I12: 0.9036279 | J12: 0.92901405 | K12: 0 | L12: 0.9034088 | M12: 0.89214325 | N12: 0.88728655 | O12: 1.0347991 | P12: 1.0566165 | Q12: 0.91065075 | R12: 0.2087688 | S12: 0.9858347 | T12: 0.90264835 | U12: 0.9080139 | V12: 0.89518605 | W12: 0.9780967 | X12: 0.90852665 | Y12: 0.03565575 | Z12: 0.9393409
A13: Odroid03 | B13: P10 | C13: 0.8898449 | D13: 0.93671945 | E13: 0.0236746 | F13: 0.92979515 | G13: 0.9080075 | H13: 1.0662841 | I13: 0.90422785 | J13: 0.9252746 | K13: 0.90478515 | L13: 0 | M13: 0.8876327 | N13: 0.91834045 | O13: 1.0184521 | P13: 0.98128775 | Q13: 0.8929664 | R13: 0.9474759 | S13: 0.02795065 | T13: 0.92880985 | U13: 0.9150962 | V13: 0.89580595 | W13: 1.0622125 | X13: 0.93469515 | Y13: 0.933602 | Z13: 0.0231885
A14: Odroid04 | B14: P11 | C14: 0.88503075 | D14: 0.92816985 | E14: 0.8935982 | F14: 0.0185156 | G14: 0.88833765 | H14: 0.9641824 | I14: 0.88491205 | J14: 0.8851359 | K14: 0.8981156 | L14: 0.88613485 | M14: 0 | N14: 0.88925255 | O14: 1.0197749 | P14: 0.9884999 | Q14: 0.88547515 | R14: 0.9016545 | S14: 0.92477415 | T14: 0.01859805 | U14: 0.8884878 | V14: 0.8851664 | W14: 1.0430726 | X14: 0.88524665 | Y14: 0.9004527 | Z14: 0.91851935
A15: Odroid05 | B15: P12 | C15: 0.8875004 | D15: 0.89774895 | E15: 0.92322685 | F15: 0.88770795 | G15: 0.0186049 | H15: 1.0364912 | I15: 0.8849691 | J15: 0.88484815 | K15: 0.8905654 | L15: 0.91167415 | M15: 0.8877275 | N15: 0 | O15: 1.021549 | P15: 0.97620985 | Q15: 0.88467395 | R15: 0.89056325 | S15: 0.9242128 | T15: 0.8885274 | U15: 0.01852515 | V15: 0.88510705 | W15: 1.0083901 | X15: 0.88475325 | Y15: 0.89886795 | Z15: 0.92443905
... A27: Odroid03 | B27: P24 | C27: 0.88884865 | D27: 0.92729285 | E27: 0.0382861 | F27: 0.91264665 | G27: 0.9064847 | H27: 1.0232467 | I27: 0.89173935 | J27: 0.8961265 | K27: 0.9420576 | L27: 0.0191884 | M27: 0.9182596 | N27: 0.9228046 | O27: 1.0019837 | P27: 0.9780991 | Q27: 0.89911055 | R27: 0.9441243 | S27: 0.02409865 | T27: 0.91041735 | U27: 0.91935585 | V27: 0.9404509 | W27: 1.1053697 | X27: 0.9233173 | Y27: 0.9861573 | Z27: 0
B31: Single core per device
A33: Odroid01 | B33: P1 | C33: 0 | D33: 0.88512695 | E33: 0.8865378 | F33: 0.8870003 | G33: 0.88717495 | H33: 0.89063695 | I33: 0.88986875
A34: Odroid02 | B34: P2 | C34: 0.884341 | D34: 0 | E34: 0.888211 | F34: 0.88822105 | G34: 0.88840815 | H34: 0.88560965 | I34: 0.885651
A35: Odroid03 | B35: P3 | C35: 0.88672065 | D35: 0.88819435 | E35: 0 | F35: 0.88837835 | G35: 0.8886756 | H35: 0.88665475 | I35: 0.8862066
A36: Odroid04 | B36: P4 | C36: 0.8847488 | D36: 0.8883407 | E36: 0.8885386 | F36: 0 | G36: 0.8882046 | H36: 0.8850042 | I36: 0.8841876
A37: Odroid05 | B37: P5 | C37: 0.8870157 | D37: 0.8886701 | E37: 0.88934085 | F37: 0.88868235 | G37: 0 | H37: 0.88461325 | I37: 0.8871294
A38: Cubie01 | B38: P6 | C38: 0.8860085 | D38: 0.88726465 | E38: 0.8884292 | F38: 0.8861537 | G38: 0.88838705 | H38: 0 | I38: 0.88942515
A39: Cubie02 | B39: P7 | C39: 0.8911494 | D39: 0.88806105 | E39: 0.88831925 | F39: 0.88770545 | G39: 0.88911615 | H39: 0.8880955 | I39: 0
C42: Odroid01 | D42: Odroid01 | E42: Odroid01 | F42: Odroid01 | G42: Odroid02 | H42: Odroid02 | I42: Odroid02 | J42: Odroid02 | K42: Odroid03 | L42: Odroid03 | M42: Odroid03 | N42: Odroid03 | O42: Odroid04 | P42: Odroid04 | Q42: Odroid04 | R42: Odroid04 | S42: Odroid05 | T42: Odroid05 | U42: Odroid05 | V42: Odroid05 | W42: Cubie01 | X42: Cubie01 | Y42: Cubie02 | Z42: Cubie02 | AA42: Raspi01 | AB42: Raspi02
C43: P0 | D43: P1 | E43: P2 | F43: P3 | G43: P4 | H43: P5 | I43: P6 | J43: P7 | K43: P8 | L43: P9 | M43: P10 | N43: P11 | O43: P12 | P43: P13 | Q43: P14 | R43: P15 | S43: P16 | T43: P17 | U43: P18 | V43: P19 | W43: P20 | X43: P21 | Y43: P22 | Z43: P23 | AA43: P24 | AB43: P25
A44: Odroid01 | B44: P0 | C44: =('Send comm performance'!C42+'Recv comm performance'!C42)/2 -> 0 | D44: =('Send comm performance'!D42+'Recv comm performance'!D42)/2 -> 0.02136645 | E44: =('Send comm performance'!E42+'Recv comm performance'!E42)/2 -> 0.018219 | F44: =('Send comm performance'!F42+'Recv comm performance'!F42)/2 -> 0.0184853 | G44: =('Send comm performance'!G42+'Recv comm performance'!G42)/2 -> 0.89417195 | H44: =('Send comm performance'!H42+'Recv comm performance'!H42)/2 -> 0.89718865 | I44: =('Send comm performance'!I42+'Recv comm performance'!I42)/2 -> 0.9294305 | J44: =('Send comm performance'!J42+'Recv comm performance'!J42)/2 -> 0.89138795 | ... AB44: =('Send comm performance'!AB42+'Recv comm performance'!AB42)/2 -> 1.3858813
A45: Odroid01 | B45: P1 | C45: =('Send comm performance'!C43+'Recv comm performance'!C43)/2 -> 0.021381 | D45: =('Send comm performance'!D43+'Recv comm performance'!D43)/2 -> 0 | E45: =('Send comm performance'!E43+'Recv comm performance'!E43)/2 -> 0.0187844 | F45: =('Send comm performance'!F43+'Recv comm performance'!F43)/2 -> 0.018905 | G45: =('Send comm performance'!G43+'Recv comm performance'!G43)/2 -> 0.9306327 | H45: =('Send comm performance'!H43+'Recv comm performance'!H43)/2 -> 0.8992944 | I45: =('Send comm performance'!I43+'Recv comm performance'!I43)/2 -> 0.89577505 | J45: =('Send comm performance'!J43+'Recv comm performance'!J43)/2 -> 0.90548575 | ... AB45: =('Send comm performance'!AB43+'Recv comm performance'!AB43)/2 -> 1.3596015
A46: Odroid01 | B46: P2 | C46: =('Send comm performance'!C44+'Recv comm performance'!C44)/2 -> 0.0184375 | D46: =('Send comm performance'!D44+'Recv comm performance'!D44)/2 -> 0.01877035 | E46: =('Send comm performance'!E44+'Recv comm performance'!E44)/2 -> 0 | F46: =('Send comm performance'!F44+'Recv comm performance'!F44)/2 -> 0.0185368 | G46: =('Send comm performance'!G44+'Recv comm performance'!G44)/2 -> 0.92851875 | H46: =('Send comm performance'!H44+'Recv comm performance'!H44)/2 -> 0.930663 | I46: =('Send comm performance'!I44+'Recv comm performance'!I44)/2 -> 0.89186455 | J46: =('Send comm performance'!J44+'Recv comm performance'!J44)/2 -> 0.90957905 | ... AB46: =('Send comm performance'!AB44+'Recv comm performance'!AB44)/2 -> 1.3732045
A47: Odroid01 | B47: P3 | C47: =('Send comm performance'!C45+'Recv comm performance'!C45)/2 -> 0.01872595 | D47: =('Send comm performance'!D45+'Recv comm performance'!D45)/2 -> 0.01888135 | E47: =('Send comm performance'!E45+'Recv comm performance'!E45)/2 -> 0.0185196 | F47: =('Send comm performance'!F45+'Recv comm performance'!F45)/2 -> 0 | G47: =('Send comm performance'!G45+'Recv comm performance'!G45)/2 -> 0.89962445 | H47: =('Send comm performance'!H45+'Recv comm performance'!H45)/2 -> 0.92080405 | I47: =('Send comm performance'!I45+'Recv comm performance'!I45)/2 -> 0.8948548 | J47: =('Send comm performance'!J45+'Recv comm performance'!J45)/2 -> 0.9132774 | ... AB47: =('Send comm performance'!AB45+'Recv comm performance'!AB45)/2 -> 1.360559
A48: Odroid02 | B48: P4 | C48: =('Send comm performance'!C46+'Recv comm performance'!C46)/2 -> 0.8916019 | D48: =('Send comm performance'!D46+'Recv comm performance'!D46)/2 -> 0.9324411 | E48: =('Send comm performance'!E46+'Recv comm performance'!E46)/2 -> 0.92805145 | F48: =('Send comm performance'!F46+'Recv comm performance'!F46)/2 -> 0.8997258 | G48: =('Send comm performance'!G46+'Recv comm performance'!G46)/2 -> 0 | H48: =('Send comm performance'!H46+'Recv comm performance'!H46)/2 -> 0.0185158 | I48: =('Send comm performance'!I46+'Recv comm performance'!I46)/2 -> 0.0385073 | J48: =('Send comm performance'!J46+'Recv comm performance'!J46)/2 -> 0.0320705 | ... AB48: =('Send comm performance'!AB46+'Recv comm performance'!AB46)/2 -> 1.2921345
A49: Odroid02 | B49: P5 | C49: =('Send comm performance'!C47+'Recv comm performance'!C47)/2 -> 0.88968395 | D49: =('Send comm performance'!D47+'Recv comm performance'!D47)/2 -> 0.9000045 | E49: =('Send comm performance'!E47+'Recv comm performance'!E47)/2 -> 0.9355894 | F49: =('Send comm performance'!F47+'Recv comm performance'!F47)/2 -> 0.91628825 | G49: =('Send comm performance'!G47+'Recv comm performance'!G47)/2 -> 0.018514 | H49: =('Send comm performance'!H47+'Recv comm performance'!H47)/2 -> 0 | I49: =('Send comm performance'!I47+'Recv comm performance'!I47)/2 -> 0.03480635 | J49: =('Send comm performance'!J47+'Recv comm performance'!J47)/2 -> 0.025666 | ... AB49: =('Send comm performance'!AB47+'Recv comm performance'!AB47)/2 -> 1.298659
A50: Odroid02 | B50: P6 | C50: =('Send comm performance'!C48+'Recv comm performance'!C48)/2 -> 0.919014 | D50: =('Send comm performance'!D48+'Recv comm performance'!D48)/2 -> 0.8926631 | E50: =('Send comm performance'!E48+'Recv comm performance'!E48)/2 -> 0.8900924 | F50: =('Send comm performance'!F48+'Recv comm performance'!F48)/2 -> 0.89485905 | G50: =('Send comm performance'!G48+'Recv comm performance'!G48)/2 -> 0.03849245 | H50: =('Send comm performance'!H48+'Recv comm performance'!H48)/2 -> 0.03483045 | I50: =('Send comm performance'!I48+'Recv comm performance'!I48)/2 -> 0 | J50: =('Send comm performance'!J48+'Recv comm performance'!J48)/2 -> 0.05487405 | ... AB50: =('Send comm performance'!AB48+'Recv comm performance'!AB48)/2 -> 1.3151241
A51: Odroid02 | B51: P7 | C51: =('Send comm performance'!C49+'Recv comm performance'!C49)/2 -> 0.88510095 | D51: =('Send comm performance'!D49+'Recv comm performance'!D49)/2 -> 0.9000673 | E51: =('Send comm performance'!E49+'Recv comm performance'!E49)/2 -> 0.90357875 | F51: =('Send comm performance'!F49+'Recv comm performance'!F49)/2 -> 0.90981125 | G51: =('Send comm performance'!G49+'Recv comm performance'!G49)/2 -> 0.0287117 | H51: =('Send comm performance'!H49+'Recv comm performance'!H49)/2 -> 0.0238117 | I51: =('Send comm performance'!I49+'Recv comm performance'!I49)/2 -> 0.04986825 | J51: =('Send comm performance'!J49+'Recv comm performance'!J49)/2 -> 0 | ... AB51: =('Send comm performance'!AB49+'Recv comm performance'!AB49)/2 -> 1.2910478
A52: Odroid03 | B52: P8 | C52: =('Send comm performance'!C50+'Recv comm performance'!C50)/2 -> 0.90233825 | D52: =('Send comm performance'!D50+'Recv comm performance'!D50)/2 -> 0.91049125 | E52: =('Send comm performance'!E50+'Recv comm performance'!E50)/2 -> 0.88606465 | F52: =('Send comm performance'!F50+'Recv comm performance'!F50)/2 -> 0.88585655 | G52: =('Send comm performance'!G50+'Recv comm performance'!G50)/2 -> 0.94747555 | H52: =('Send comm performance'!H50+'Recv comm performance'!H50)/2 -> 0.94267895 | I52: =('Send comm performance'!I50+'Recv comm performance'!I50)/2 -> 0.898747 | J52: =('Send comm performance'!J50+'Recv comm performance'!J50)/2 -> 0.96979295 | ... AB52: =('Send comm performance'!AB50+'Recv comm performance'!AB50)/2 -> 1.3111393
A53: Odroid03 | B53: P9 | C53: =('Send comm performance'!C51+'Recv comm performance'!C51)/2 -> 0.9275864 | D53: =('Send comm performance'!D51+'Recv comm performance'!D51)/2 -> 0.89380885 | E53: =('Send comm performance'!E51+'Recv comm performance'!E51)/2 -> 0.90196385 | F53: =('Send comm performance'!F51+'Recv comm performance'!F51)/2 -> 0.9018958 | G53: =('Send comm performance'!G51+'Recv comm performance'!G51)/2 -> 0.962244 | H53: =('Send comm performance'!H51+'Recv comm performance'!H51)/2 -> 0.98871885 | I53: =('Send comm performance'!I51+'Recv comm performance'!I51)/2 -> 0.9227477 | J53: =('Send comm performance'!J51+'Recv comm performance'!J51)/2 -> 0.9301754 | ... AB53: =('Send comm performance'!AB51+'Recv comm performance'!AB51)/2 -> 1.3232921
A54: Odroid03 | B54: P10 | C54: =('Send comm performance'!C52+'Recv comm performance'!C52)/2 -> 0.90096345 | D54: =('Send comm performance'!D52+'Recv comm performance'!D52)/2 -> 0.9062415 | E54: =('Send comm performance'!E52+'Recv comm performance'!E52)/2 -> 0.8990978 | F54: =('Send comm performance'!F52+'Recv comm performance'!F52)/2 -> 0.94239425 | G54: =('Send comm performance'!G52+'Recv comm performance'!G52)/2 -> 0.95562075 | H54: =('Send comm performance'!H52+'Recv comm performance'!H52)/2 -> 0.9323977 | I54: =('Send comm performance'!I52+'Recv comm performance'!I52)/2 -> 0.9561543 | J54: =('Send comm performance'!J52+'Recv comm performance'!J52)/2 -> 0.9763907 | ... AB54: =('Send comm performance'!AB52+'Recv comm performance'!AB52)/2 -> 1.270467
A55: Odroid03 | B55: P11 | C55: =('Send comm performance'!C53+'Recv comm performance'!C53)/2 -> 0.89296375 | D55: =('Send comm performance'!D53+'Recv comm performance'!D53)/2 -> 0.88750045 | E55: =('Send comm performance'!E53+'Recv comm performance'!E53)/2 -> 0.90160535 | F55: =('Send comm performance'!F53+'Recv comm performance'!F53)/2 -> 0.89252735 | G55: =('Send comm performance'!G53+'Recv comm performance'!G53)/2 -> 0.9659184 | H55: =('Send comm performance'!H53+'Recv comm performance'!H53)/2 -> 0.9163133 | I55: =('Send comm performance'!I53+'Recv comm performance'!I53)/2 -> 0.96032205 | J55: =('Send comm performance'!J53+'Recv comm performance'!J53)/2 -> 0.8879528 | ... AB55: =('Send comm performance'!AB53+'Recv comm performance'!AB53)/2 -> 1.3075936
... A69: Raspi02 | B69: P25 | C69: =('Send comm performance'!C67+'Recv comm performance'!C67)/2 -> 1.3883293 | D69: =('Send comm performance'!D67+'Recv comm performance'!D67)/2 -> 1.37166 | E69: =('Send comm performance'!E67+'Recv comm performance'!E67)/2 -> 1.3817179 | F69: =('Send comm performance'!F67+'Recv comm performance'!F67)/2 -> 1.3705477 | G69: =('Send comm performance'!G67+'Recv comm performance'!G67)/2 -> 1.2988412 | H69: =('Send comm performance'!H67+'Recv comm performance'!H67)/2 -> 1.3049122 | I69: =('Send comm performance'!I67+'Recv comm performance'!I67)/2 -> 1.3189339 | J69: =('Send comm performance'!J67+'Recv comm performance'!J67)/2 -> 1.2997543 | ... AB69: =('Send comm performance'!AB67+'Recv comm performance'!AB67)/2 -> 0

Sheet Send comm performance
C1: P1 | D1: P2 | E1: P3 | F1: P4 | G1: P5 | H1: P6 | I1: P7 | J1: P8 | K1: P9 | L1: P10 | M1: P11 | N1: P12 | O1: P13 | P1: P14 | Q1: P15 | R1: P16 | S1: P17 | T1: P18 | U1: P19 | V1: P20 | W1: P21 | X1: P22 | Y1: P23 | Z1: P24
B2: P1 | C2: 0 | D2: 0.8912199 | E2: 0.8765662 | F2: 0.8801889 | G2: 0.8795443 | H2: 0.8760173 | I2: 0.981375 | J2: 0.0186582 | K2: 0.9669995 | L2: 0.888149 | M2: 0.8825378 | N2: 0.8802631 | O2: 1.0144064 | P2: 1.0379646 | Q2: 0.01841 | R2: 0.9122968 | S2: 0.9224546 | T2: 0.8823981 | U2: 0.882395 | V2: 0.9555602 | W2: 1.0331392 | X2: 0.0188882 | Y2: 0.9700627 | Z2: 0.8796251
B3: P2 | C3: 0.8829825 | D3: 0 | E3: 0.9827137 | F3: 0.8795066 | G3: 0.8816216 | H3: 1.0203795 | I3: 0.8818412 | J3: 0.8823662 | K3: 0.0188491 | L3: 0.9160836 | M3: 0.9026108 | N3: 0.8820705 | O3: 1.0238538 | P3: 1.0471017 | Q3: 0.8774562 | R3: 0.0190468 | S3: 1.0048656 | T3: 0.8824506 | U3: 0.8833897 | V3: 0.9553852 | W3: 1.1554513 | X3: 0.8895409 | Y3: 0.0382831 | Z3: 0.8891573
B4: P3 | C4: 0.8791552 | D4: 0.9176507 | E4: 0 | F4: 0.9227242 | G4: 0.9078526 | H4: 0.9180233 | I4: 0.8753512 | J4: 0.8784523 | K4: 0.9176292 | L4: 0.030189 | M4: 0.8831844 | N4: 0.8825083 | O4: 1.0287967 | P4: 1.0077519 | Q4: 0.8862886 | R4: 0.8953693 | S4: 0.0389874 | T4: 0.8903739 | U4: 0.8862312 | V4: 1.0096087 | W4: 1.1026773 | X4: 0.8868771 | Y4: 0.9689164 | Z4: 0.0284009
B5: P4 | C5: 0.879921 | D5: 0.9395027 | E5: 0.9293122 | F5: 0 | G5: 0.8813756 | H5: 1.014199 | I5: 0.8753529 | J5: 0.8762412 | K5: 0.9585867 | L5: 0.9643421 | M5: 0.0188937 | N5: 0.8840117 | O5: 1.0555408 | P5: 1.0878096 | Q5: 0.8765996 | R5: 0.9843736 | S5: 0.8820238 | T5: 0.0191741 | U5: 0.8834119 | V5: 0.8767247 | W5: 1.0574412 | X5: 0.8762379 | Y5: 0.9670925 | Z5: 0.9367471
B6: P5 | C6: 0.8751047 | D6: 0.8815215 | E6: 0.8927917 | F6: 0.8773792 | G6: 0 | H6: 1.0711834 | I6: 0.8752279 | J6: 0.8763788 | K6: 0.9338944 | L6: 0.9200635 | M6: 0.8827794 | N6: 0.0186813 | O6: 1.003602 | P6: 0.9980478 | Q6: 0.8769836 | R6: 0.9623256 | S6: 0.9619265 | T6: 0.88289 | U6: 0.0184944 | V6: 0.8847327 | W6: 0.9984415 | X6: 0.8767371 | Y6: 0.9477761 | Z6: 0.9160826
B7: P6 | C7: 1.0020514 | D7: 1.0229814 | E7: 0.9458458 | F7: 0.9399304 | G7: 0.9346509 | H7: 0 | I7: 1.0000927 | J7: 1.0419855 | K7: 1.0695963 | L7: 1.0764296 | M7: 0.9301817 | N7: 0.9506917 | O7: 1.0001972 | P7: 1.0701897 | Q7: 0.9400609 | R7: 0.9903321 | S7: 1.0354798 | T7: 0.9714158 | U7: 0.990206 | V7: 0.0899642 | W7: 1.0273981 | X7: 0.9303579 | Y7: 1.0401001 | Z7: 1.0198755
B8: P7 | C8: 0.8828537 | D8: 0.9485466 | E8: 0.8823922 | F8: 0.8823779 | G8: 0.8810248 | H8: 1.1485407 | I8: 0 | J8: 0.8834178 | K8: 0.9137449 | L8: 0.9341309 | M8: 0.8840327 | N8: 0.8811419 | O8: 1.0096474 | P8: 0.0821643 | Q8: 0.8795002 | R8: 0.9459529 | S8: 0.8829336 | T8: 0.8836432 | U8: 0.8837273 | V8: 0.8862247 | W8: 0.0786808 | X8: 0.8795221 | Y8: 0.9607215 | Z8: 0.8943882
B9: P8 | C9: 0.0181437 | D9: 0.9808023 | E9: 0.9021175 | F9: 0.8810399 | G9: 0.8796875 | H9: 1.0745859 | I9: 0.8751776 | J9: 0 | K9: 0.9716887 | L9: 0.9663627 | M9: 0.8810749 | N9: 0.8826621 | O9: 1.0214016 | P9: 1.0117719 | Q9: 0.0192907 | R9: 0.999393 | S9: 0.9122744 | T9: 0.8826523 | U9: 0.8822732 | V9: 0.8766768 | W9: 0.9999759 | X9: 0.0196271 | Y9: 0.90101 | Z9: 0.9017861
B10: P9 | C10: 0.8790936 | D10: 0.0371487 | E10: 0.9541519 | F10: 0.8817654 | G10: 0.8818188 | H10: 0.9928596 | I10: 0.8822074 | J10: 0.8783166 | K10: 0 | L10: 0.9094167 | M10: 0.8790462 | N10: 0.880949 | O10: 1.0155559 | P10: 1.0082221 | Q10: 0.8769217 | R10: 0.037955 | S10: 0.9004409 | T10: 0.9105759 | U10: 0.8966448 | V10: 0.8893263 | W10: 1.0003109 | X10: 0.8964417 | Y10: 0.0287521 | Z10: 0.8836462
B11: P10 | C11: 0.8785393 | D11: 0.9457653 | E11: 0.0184605 | F11: 0.879494 | G11: 0.8827941 | H11: 1.0610275 | I11: 0.8801212 | J11: 0.8747282 | K11: 0.8844118 | L11: 0 | M11: 0.8815634 | N11: 0.8913982 | O11: 1.0647123 | P11: 1.0076988 | Q11: 0.8819916 | R11: 0.9718876 | S11: 0.0282128 | T11: 0.8818688 | U11: 0.8892756 | V11: 0.8887608 | W11: 1.081234 | X11: 0.8820236 | Y11: 0.8829453 | Z11: 0.0189674
B12: P11 | C12: 0.8750663 | D12: 0.9483271 | E12: 0.8888133 | F12: 0.0181122 | G12: 0.8815444 | H12: 0.9919825 | I12: 0.8754721 | J12: 0.8752353 | K12: 0.9003751 | L12: 0.8772385 | M12: 0 | N12: 0.8848972 | O12: 1.0255623 | P12: 1.0217445 | Q12: 0.8772354 | R12: 0.9071939 | S12: 0.9556582 | T12: 0.0190544 | U12: 0.883095 | V12: 0.8769786 | W12: 1.1391273 | X12: 0.8769834 | Y12: 0.8993556 | Z12: 0.9424834
B13: P12 | C13: 0.8807099 | D13: 0.8995168 | E13: 0.9505856 | F13: 0.879915 | G13: 0.0185051 | H13: 1.1089406 | I13: 0.8752062 | J13: 0.8749738 | K13: 0.8829694 | L13: 0.9278641 | M13: 0.8798165 | N13: 0 | O13: 1.0339062 | P13: 1.0015566 | Q13: 0.8762286 | R13: 0.887038 | S13: 0.9431419 | T13: 0.8833878 | U13: 0.0190721 | V13: 0.8773329 | W13: 1.0776565 | X13: 0.876359 | Y13: 0.9023132 | Z13: 0.9363515
... B25: P24 | C25: 0.8840446 | D25: 0.9611793 | E25: 0.0574434 | F25: 0.8787305 | G25: 0.8821485 | H25: 1.0214481 | I25: 0.8784425 | J25: 0.8822191 | K25: 0.986233 | L25: 0.0193744 | M25: 0.8835187 | N25: 0.8905246 | O25: 1.0422308 | P25: 1.0055604 | Q25: 0.8815176 | R25: 0.9070911 | S25: 0.0194788 | T25: 0.8867953 | U25: 0.9102449 | V25: 0.9092021 | W25: 1.176652 | X25: 0.8814814 | Y25: 0.965939 | Z25: 0
B29: Single core per device
B31: P1 | C31: 0 | D31: 0.8780336 | E31: 0.8803761 | F31: 0.8815136 | G31: 0.8815534 | H31: 0.8893278 | I31: 0.8871367
B32: P2 | C32: 0.875109 | D32: 0 | E32: 0.8820665 | F32: 0.8818176 | G32: 0.88257 | H32: 0.8779378 | I32: 0.8778107
B33: P3 | C33: 0.8779681 | D33: 0.8822885 | E33: 0 | F33: 0.8825061 | G33: 0.8823712 | H33: 0.8802674 | I33: 0.8787584
B34: P4 | C34: 0.8756342 | D34: 0.8823154 | E34: 0.8826075 | F34: 0 | G34: 0.882185 | H34: 0.8766406 | I34: 0.8751173
B35: P5 | C35: 0.8805304 | D35: 0.882355 | E35: 0.8826873 | F35: 0.8825712 | G35: 0 | H35: 0.8760483 | I35: 0.8807709
B36: P6 | C36: 0.8777657 | D36: 0.8824697 | E36: 0.8843923 | F36: 0.8797972 | G36: 0.8845217 | H36: 0 | I36: 0.8847623
B37: P7 | C37: 0.8809471 | D37: 0.8839014 | E37: 0.8841872 | F37: 0.8830063 | G37: 0.8828616 | H37: 0.883316 | I37: 0
C40: Odroid01 | D40: Odroid01 | E40: Odroid01 | F40: Odroid01 | G40: Odroid02 | H40: Odroid02 | I40: Odroid02 | J40: Odroid02 | K40: Odroid03 | L40: Odroid03 | M40: Odroid03 | N40: Odroid03 | O40: Odroid04 | P40: Odroid04 | Q40: Odroid04 | R40: Odroid04 | S40: Odroid05 | T40: Odroid05 | U40: Odroid05 | V40: Odroid05 | W40: Cubie01 | X40: Cubie01 | Y40: Cubie02 | Z40: Cubie02 | AA40: Raspi01 | AB40: Raspi02
C41: P0 | D41: P1 | E41: P2 | F41: P3 | G41: P4 | H41: P5 | I41: P6 | J41: P7 | K41: P8 | L41: P9 | M41: P10 | N41: P11 | O41: P12 | P41: P13 | Q41: P14 | R41: P15 | S41: P16 | T41: P17 | U41: P18 | V41: P19 | W41: P20 | X41: P21 | Y41: P22 | Z41: P23 | AA41: P24 | AB41: P25
A42: Odroid01 | B42: P0 | C42: 0 | D42: 0.0192542 | E42: 0.0186517 | F42: 0.0186751 | G42: 0.890368 | H42: 0.8996465 | I42: 0.9568675 | J42: 0.8809066 | K42: 0.9120047 | L42: 0.9703116 | M42: 0.9049296 | N42: 0.8807523 | O42: 0.9797554 | P42: 0.890564 | Q42: 0.8975503 | R42: 0.9698422 | S42: 0.8862314 | T42: 0.9018123 | U42: 0.8889444 | V42: 0.939852 | W42: 0.8779826 | X42: 1.0943558 | Y42: 0.9496608 | Z42: 1.0473671 | AA42: 1.1923101 | AB42: 1.0853646
A43: Odroid01 | B43: P1 | C43: 0.0230155 | D43: 0 | E43: 0.0185223 | F43: 0.0197701 | G43: 0.9632487 | H43: 0.9063492 | I43: 0.8908846 | J43: 0.9152391 | K43: 0.9201081 | L43: 0.8962259 | M43: 0.9115038 | N43: 0.8909366 | O43: 0.9013438 | P43: 0.9822519 | Q43: 1.0058866 | R43: 0.9023685 | S43: 0.9560909 | T43: 0.9035075 | U43: 0.9104898 | V43: 0.8780191 | W43: 0.8762283 | X43: 1.0278237 | Y43: 0.8758714 | Z43: 1.0213287 | AA43: 1.1519673 | AB43: 1.0463724
A44: Odroid01 | B44: P2 | C44: 0.0177338 | D44: 0.0189908 | E44: 0 | F44: 0.0186849 | G44: 0.9646699 | H44: 0.9674461 | I44: 0.8913603 | J44: 0.9268072 | K44: 0.8805406 | L44: 0.9104791 | M44: 0.8930407 | N44: 0.8978469 | O44: 0.9078526 | P44: 0.9198229 | Q44: 0.8870292 | R44: 0.9157443 | S44: 0.9496365 | T44: 0.8808208 | U44: 0.9181526 | V44: 0.9659052 | W44: 0.8758707 | X44: 1.0151861 | Y44: 0.8761199 | Z44: 1.0154235 | AA44: 1.1412225 | AB44: 1.0485661
A45: Odroid01 | B45: P3 | C45: 0.0182323 | D45: 0.0179675 | E45: 0.0183291 | F45: 0 | G45: 0.9004159 | H45: 0.9482315 | I45: 0.8974731 | J45: 0.9195433 | K45: 0.8835166 | L45: 0.9087968 | M45: 0.9827349 | N45: 0.8875239 | O45: 0.9430926 | P45: 0.9681818 | Q45: 0.9084208 | R45: 0.9430361 | S45: 0.8793654 | T45: 0.9501731 | U45: 0.9002934 | V45: 0.9052939 | W45: 0.8761282 | X45: 1.0722454 | Y45: 0.8759902 | Z45: 1.031378 | AA45: 1.1457229 | AB45: 1.0400245
A46: Odroid02 | B46: P4 | C46: 0.8795123 | D46: 0.8833661 | E46: 0.8785362 | F46: 0.886652 | G46: 0 | H46: 0.019021 | I46: 0.039077 | J46: 0.0313637 | K46: 0.9832656 | L46: 0.9362893 | M46: 0.9730504 | N46: 0.9216313 | O46: 0.8917994 | P46: 0.8977571 | Q46: 0.8799593 | R46: 0.8878992 | S46: 0.9004982 | T46: 0.8818657 | U46: 0.8940942 | V46: 0.9461498 | W46: 0.8888922 | X46: 1.0768831 | Y46: 0.8759527 | Z46: 1.0204773 | AA46: 1.171216 | AB46: 1.0793061
A47: Odroid02 | B47: P5 | C47: 0.8783543 | D47: 0.8757274 | E47: 0.8818793 | F47: 0.8803737 | G47: 0.017976 | H47: 0 | I47: 0.0316455 | J47: 0.0184026 | K47: 0.8895206 | L47: 0.9959409 | M47: 0.8833947 | N47: 0.8953674 | O47: 0.8854396 | P47: 0.9372699 | Q47: 0.9112592 | R47: 0.9403846 | S47: 0.8893635 | T47: 0.9185879 | U47: 0.8830531 | V47: 0.935149 | W47: 0.876493 | X47: 1.0009806 | Y47: 0.8781881 | Z47: 1.0357673 | AA47: 1.1904917 | AB47: 1.0880268
A48: Odroid02 | B48: P6 | C48: 0.875376 | D48: 0.8761389 | E48: 0.8765891 | F48: 0.8878474 | G48: 0.037879 | H48: 0.0417109 | I48: 0 | J48: 0.0723052 | K48: 0.907002 | L48: 0.8803422 | M48: 1.006886 | N48: 0.8857193 | O48: 0.9422631 | P48: 1.000427 | Q48: 0.8989022 | R48: 0.9121635 | S48: 0.9114537 | T48: 0.9640899 | U48: 0.9698479 | V48: 0.9119568 | W48: 0.9073937 | X48: 1.0603638 | Y48: 0.8855157 | Z48: 1.0155206 | AA48: 1.2064545 | AB48: 1.0737729
A49: Odroid02 | B49: P7 | C49: 0.8759141 | D49: 0.8756022 | E49: 0.875088 | F49: 0.8844995 | G49: 0.0290251 | H49: 0.0291882 | I49: 0.037385 | J49: 0 | K49: 0.9591022 | L49: 0.9388642 | M49: 1.0016086 | N49: 0.88289 | O49: 0.881587 | P49: 0.9058175 | Q49: 0.9879317 | R49: 0.9436505 | S49: 0.9537461 | T49: 0.9719045 | U49: 0.9681587 | V49: 0.885776 | W49: 0.8808408 | X49: 1.0363922 | Y49: 0.8839836 | Z49: 1.0711102 | AA49: 1.1753964 | AB49: 1.0960953
A50: Odroid03 | B50: P8 | C50: 0.8845508 | D50: 0.8853853 | E50: 0.87749 | F50: 0.8776627 | G50: 0.8955765 | H50: 0.9835515 | I50: 0.8786092 | J50: 0.9639218 | K50: 0 | L50: 0.1579692 | M50: 0.2481573 | N50: 0.0545244 | O50: 0.8984478 | P50: 1.0048823 | Q50: 0.9606013 | R50: 0.8868954 | S50: 0.9016387 | T50: 0.9176598 | U50: 0.8939435 | V50: 0.9141932 | W50: 0.8862758 | X50: 1.1553237 | Y50: 0.8862734 | Z50: 1.0747917 | AA50: 1.1759465 | AB50: 1.0828612
A51: Odroid03 | B51: P9 | C51: 0.8760974 | D51: 0.8763497 | E51: 0.8751161 | F51: 0.8770285 | G51: 0.9794657 | H51: 0.9680061 | I51: 0.9502177 | J51: 0.9109342 | K51: 0.0186863 | L51: 0 | M51: 0.0387688 | N51: 0.0206554 | O51: 0.908483 | P51: 0.9826207 | Q51: 1.0411141 | R51: 0.8905149 | S51: 0.9525547 | T51: 0.9417417 | U51: 0.8861098 | V51: 0.9855938 | W51: 0.876941 | X51: 1.0289538 | Y51: 0.8770938 | Z51: 1.0139546 | AA51: 1.1725168 | AB51: 1.1024296
A52: Odroid03 | B52: P10 | C52: 0.878428 | D52: 0.8928382 | E52: 0.8909259 | F52: 0.8903608 | G52: 0.9236097 | H52: 0.9694223 | I52: 0.9010653 | J52: 0.935024 | K52: 0.0182309 | L52: 0.0289996 | M52: 0 | N52: 0.0200019 | O52: 0.8923955 | P52: 0.9002752 | Q52: 1.0232029 | R52: 0.9069464 | S52: 0.9060495 | T52: 0.8874764 | U52: 0.9942272 | V52: 0.8828256 | W52: 0.8770757 | X52: 1.0006897 | Y52: 0.8767359 | Z52: 1.0179393 | AA52: 1.1755245 | AB52: 1.0760291
A53: Odroid03 | B53: P11 | C53: 0.891278 | D53: 0.8752356 | E53: 0.8869085 | F53: 0.8840165 | G53: 0.993335 | H53: 0.9267333 | I53: 1.0109861 | J53: 0.8809936 | K53: 0.0203066 | L53: 0.0382545 | M53: 0.0181181 | N53: 0 | O53: 0.9741592 | P53: 0.9188931 | Q53: 0.9323523 | R53: 0.9421592 | S53: 0.9024184 | T53: 0.8951948 | U53: 0.9120846 | V53: 0.9661269 | W53: 0.8817523 | X53: 1.0577114 | Y53: 0.8789165 | Z53: 1.1010041 | AA53: 1.1702046 | AB53: 1.0729349
... A67: Raspi02 | B67: P25 | C67: 1.6856549 | D67: 1.6795299 | E67: 1.7032425 | F67: 1.6803391 | G67: 1.5066509 | H67: 1.5065939 | I67: 1.5552721 | J67: 1.4846392 | K67: 1.5269847 | L67: 1.5525191 | M67: 1.4639876 | N67: 1.5313296 | O67: 1.4664664 | P67: 1.4677763 | Q67: 1.497411 | R67: 1.5195746 | S67: 1.3947625 | T67: 1.4580717 | U67: 1.4043686 | V67: 1.4685984 | W67: 1.6939497 | X67: 1.5077679 | Y67: 1.6742492 | Z67: 1.4397249 | AA67: 1.3278596 | AB67: 0

Sheet Recv comm performance
C1: P1 | D1: P2 | E1: P3 | F1: P4 | G1: P5 | H1: P6 | I1: P7 | J1: P8 | K1: P9 | L1: P10 | M1: P11 | N1: P12 | O1: P13 | P1: P14 | Q1: P15 | R1: P16 | S1: P17 | T1: P18 | U1: P19 | V1: P20 | W1: P21 | X1: P22 | Y1: P23 | Z1: P24
B2: P1 | C2: 0 | D2: 0.8923988 | E2: 0.8922257 | F2: 0.8922467 | G2: 0.8918381 | H2: 1.0137613 | I2: 0.8926027 | J2: 0.0181851 | K2: 0.8958788 | L2: 0.9040861 | M2: 0.8917544 | N2: 0.8963575 | O2: 1.0058975 | P2: 0.9371381 | Q2: 0.0180104 | R2: 0.8919044 | S2: 0.8923755 | T2: 0.8918862 | U2: 0.8919127 | V2: 0.8921485 | W2: 0.9494476 | X2: 0.0177696 | Y2: 0.9034951 | Z2: 0.8984399
B3: P2 | C3: 0.8932242 | D3: 0 | E3: 0.9223351 | F3: 0.9567947 | G3: 0.8936696 | H3: 1.0271509 | I3: 0.9580522 | J3: 0.9955366 | K3: 0.0372243 | L3: 0.9574854 | M3: 0.9560337 | N3: 0.916765 | O3: 0.9555254 | P3: 1.0900707 | Q3: 0.8975718 | R3: 0.0177181 | S3: 0.947139 | T3: 0.9508564 | U3: 0.8937604 | V3: 0.9215596 | W3: 1.1031845 | X3: 0.9070597 | Y3: 0.0185149 | Z3: 0.9929461
B4: P3 | C4: 0.8936174 | D4: 1.0017216 | E4: 0 | F4: 0.9443402 | G4: 0.9054005 | H4: 0.9502456 | I4: 0.8931115 | J4: 0.9169326 | K4: 0.9565735 | L4: 0.0185411 | M4: 0.8933911 | N4: 0.9666471 | O4: 0.9859667 | P4: 0.9636407 | Q4: 0.8933606 | R4: 0.9325161 | S4: 0.034554 | T4: 0.893306 | U4: 0.9091527 | V4: 0.9268489 | W4: 1.0401087 | X4: 0.9038386 | Y4: 0.9180484 | Z4: 0.0582526
B5: P4 | C5: 0.8964708 | D5: 0.8959794 | E5: 0.9262631 | F5: 0 | G5: 0.8982296 | H5: 0.9439116 | I5: 0.892987 | J5: 0.8936579 | K5: 0.8942075 | L5: 0.8943975 | M5: 0.0181863 | N5: 0.8936124 | O5: 0.9414856 | P5: 0.939986 | Q5: 0.8934908 | R5: 0.8942251 | S5: 0.9225066 | T5: 0.0178146 | U5: 0.8938739 | V5: 0.8959219 | W5: 0.9487944 | X5: 0.8937521 | Y5: 0.903363 | Z5: 0.8949864
B6: P5 | C6: 0.8931222 | D6: 0.8962202 | E6: 0.9164822 | F6: 0.8936384 | G6: 0 | H6: 0.9370568 | I6: 0.8933585 | J6: 0.8932576 | K6: 0.8967593 | L6: 0.9012167 | M6: 0.8937774 | N6: 0.01858 | O6: 0.9784026 | P6: 0.9627237 | Q6: 0.8930109 | R6: 0.8941145 | S6: 0.8968856 | T6: 0.8943751 | U6: 0.0189502 | V6: 0.8928363 | W6: 0.9343612 | X6: 0.8933461 | Y6: 0.8993478 | Z6: 0.896719
B7: P6 | C7: 0.8923516 | D7: 1.0254176 | E7: 0.9364579 | F7: 1.0216405 | G7: 1.0774291 | H7: 0 | I7: 1.1612384 | J7: 1.10303 | K7: 0.9977429 | L7: 1.0663557 | M7: 1.0137658 | N7: 1.1416855 | O7: 0.9765401 | P7: 1.2064557 | Q7: 1.070451 | R7: 1.1199172 | S7: 1.0009246 | T7: 1.0601492 | U7: 1.019367 | V7: 0.0656567 | W7: 1.1104116 | X7: 1.0192804 | Y7: 1.1640935 | Z7: 1.0289836
B8: P7 | C8: 0.9901016 | D8: 0.8938303 | E8: 0.8921728 | F8: 0.8923304 | G8: 0.8922086 | H8: 1.0054934 | I8: 0 | J8: 0.89165 | K8: 0.8974712 | L8: 0.8920934 | M8: 0.8922994 | N8: 0.8921473 | O8: 1.0089915 | P8: 0.0737422 | Q8: 0.8916457 | R8: 0.9004159 | S8: 0.8973038 | T8: 0.8923018 | U8: 0.8921621 | V8: 0.8921461 | W8: 0.0712354 | X8: 0.8919668 | Y8: 0.8949542 | Z8: 0.894443
B9: P8 | C9: 0.0191939 | D9: 0.8951948 | E9: 0.8935652 | F9: 0.8934176 | G9: 0.8936977 | H9: 1.0587008 | I9: 0.8930099 | J9: 0 | K9: 0.8920305 | L9: 0.8922102 | M9: 0.8923173 | N9: 0.8923116 | O9: 0.9542046 | P9: 0.9581769 | Q9: 0.0187209 | R9: 0.8926344 | S9: 0.9091885 | T9: 0.8923233 | U9: 0.8924246 | V9: 0.8993213 | W9: 0.9465935 | X9: 0.0181 | Y9: 0.8998973 | Z9: 0.8959091
B10: P9 | C10: 0.973685 | D10: 0.0188711 | E10: 0.9259591 | F10: 0.9633279 | G10: 0.9450455 | H10: 1.0717392 | I10: 0.9250484 | J10: 0.9797115 | K10: 0 | L10: 0.8974009 | M10: 0.9052403 | N10: 0.8936241 | O10: 1.0540423 | P10: 1.105011 | Q10: 0.9443798 | R10: 0.3795826 | S10: 1.0712285 | T10: 0.8947208 | U10: 0.919383 | V10: 0.9010458 | W10: 0.9558825 | X10: 0.9206116 | Y10: 0.0425594 | Z10: 0.9950356
B11: P10 | C11: 0.9011505 | D11: 0.9276736 | E11: 0.0288887 | F11: 0.9800963 | G11: 0.9332209 | H11: 1.0715408 | I11: 0.9283345 | J11: 0.975821 | K11: 0.9251585 | L11: 0 | M11: 0.893702 | N11: 0.9452827 | O11: 0.9721918 | P11: 0.9548767 | Q11: 0.9039412 | R11: 0.9230642 | S11: 0.0276885 | T11: 0.9757509 | U11: 0.9409168 | V11: 0.9028511 | W11: 1.043191 | X11: 0.9873667 | Y11: 0.9842587 | Z11: 0.0274096
B12: P11 | C12: 0.8949952 | D12: 0.9080126 | E12: 0.8983831 | F12: 0.018919 | G12: 0.8951309 | H12: 0.9363823 | I12: 0.894352 | J12: 0.8950365 | K12: 0.8958561 | L12: 0.8950312 | M12: 0 | N12: 0.8936079 | O12: 1.0139875 | P12: 0.9552553 | Q12: 0.8937149 | R12: 0.8961151 | S12: 0.8938901 | T12: 0.0181417 | U12: 0.8938806 | V12: 0.8933542 | W12: 0.9470179 | X12: 0.8935099 | Y12: 0.9015498 | Z12: 0.8945553
B13: P12 | C13: 0.8942909 | D13: 0.8959811 | E13: 0.8958681 | F13: 0.8955009 | G13: 0.0187047 | H13: 0.9640417 | I13: 0.894732 | J13: 0.8947225 | K13: 0.8981614 | L13: 0.8954842 | M13: 0.8956385 | N13: 0 | O13: 1.0091918 | P13: 0.9508631 | Q13: 0.8931193 | R13: 0.8940885 | S13: 0.9052837 | T13: 0.893667 | U13: 0.0179782 | V13: 0.8928812 | W13: 0.9391236 | X13: 0.8931475 | Y13: 0.8954227 | Z13: 0.9125266
... B25: P24 | C25: 0.8936527 | D25: 0.8934064 | E25: 0.0191288 | F25: 0.9465628 | G25: 0.9308209 | H25: 1.0250454 | I25: 0.9050362 | J25: 0.9100339 | K25: 0.8978822 | L25: 0.0190024 | M25: 0.9530005 | N25: 0.9550846 | O25: 0.9617367 | P25: 0.9506378 | Q25: 0.9167035 | R25: 0.9811575 | S25: 0.0287185 | T25: 0.9340394 | U25: 0.9284668 | V25: 0.9716997 | W25: 1.0340874 | X25: 0.9651532 | Y25: 1.0063756 | Z25: 0
B29: Single core per device
B31: P1 | C31: 0 | D31: 0.8922203 | E31: 0.8926995 | F31: 0.892487 | G31: 0.8927965 | H31: 0.8919461 | I31: 0.8926008
B32: P2 | C32: 0.893573 | D32: 0 | E32: 0.8943555 | F32: 0.8946245 | G32: 0.8942463 | H32: 0.8932815 | I32: 0.8934913
B33: P3 | C33: 0.8954732 | D33: 0.8941002 | E33: 0 | F33: 0.8942506 | G33: 0.89498 | H33: 0.8930421 | I33: 0.8936548
B34: P4 | C34: 0.8938634 | D34: 0.894366 | E34: 0.8944697 | F34: 0 | G34: 0.8942242 | H34: 0.8933678 | I34: 0.8932579
B35: P5 | C35: 0.893501 | D35: 0.8949852 | E35: 0.8959944 | F35: 0.8947935 | G35: 0 | H35: 0.8931782 | I35: 0.8934879
B36: P6 | C36: 0.8942513 | D36: 0.8920596 | E36: 0.8924661 | F36: 0.8925102 | G36: 0.8922524 | H36: 0 | I36: 0.894088
B37: P7 | C37: 0.9013517 | D37: 0.8922207 | E37: 0.8924513 | F37: 0.8924046 | G37: 0.8953707 | H37: 0.892875 | I37: 0
C40: Odroid01 | D40: Odroid01 | E40: Odroid01 | F40: Odroid01 | G40: Odroid02 | H40: Odroid02 | I40: Odroid02 | J40: Odroid02 | K40: Odroid03 | L40: Odroid03 | M40: Odroid03 | N40: Odroid03 | O40: Odroid04 | P40: Odroid04 | Q40: Odroid04 | R40: Odroid04 | S40: Odroid05 | T40: Odroid05 | U40: Odroid05 | V40: Odroid05 | W40: Cubie01 | X40: Cubie01 | Y40: Cubie02 | Z40: Cubie02 | AA40: Raspi01 | AB40: Raspi02
C41: P0 | D41: P1 | E41: P2 | F41: P3 | G41: P4 | H41: P5 | I41: P6 | J41: P7 | K41: P8 | L41: P9 | M41: P10 | N41: P11 | O41: P12 | P41: P13 | Q41: P14 | R41: P15 | S41: P16 | T41: P17 | U41: P18 | V41: P19 | W41: P20 | X41: P21 | Y41: P22 | Z41: P23 | AA41: P24 | AB41: P25
A42: Odroid01 | B42: P0 | C42: 0 | D42: 0.0234787 | E42: 0.0177863 | F42: 0.0182955 | G42: 0.8979759 | H42: 0.8947308 | I42: 0.9019935 | J42: 0.9018693 | K42: 0.8978505 | L42: 0.8930261 | M42: 0.8936038 | N42: 0.9054544 | O42: 0.8978608 | P42: 0.8925228 | Q42: 0.8925824 | R42: 0.8994868 | S42: 0.8924816 | T42: 0.8923903 | U42: 0.910228 | V42: 0.9009488 | W42: 0.8923624 | X42: 1.0021219 | Y42: 0.8926063 | Z42: 1.0609987 | AA42: 2.0410721 | AB42: 1.686398
A43: Odroid01 | B43: P1 | C43: 0.0197465 | D43: 0 | E43: 0.0190465 | F43: 0.0180399 | G43: 0.8980167 | H43: 0.8922396 | I43: 0.9006655 | J43: 0.8957324 | K43: 0.8983839 | L43: 0.8926356 | M43: 0.9026113 | N43: 0.9004993 | O43: 0.9002111 | P43: 0.89275 | Q43: 0.8979354 | R43: 0.9023945 | S43: 0.8923247 | T43: 0.8923621 | U43: 0.9007361 | V43: 0.8938317 | W43: 0.892118 | X43: 0.9648445 | Y43: 0.8929772 | Z43: 0.9651496 | AA43: 2.0947509 | AB43: 1.6728306
A44: Odroid01 | B44: P2 | C44: 0.0191412 | D44: 0.0185499 | E44: 0 | F44: 0.0183887 | G44: 0.8923676 | H44: 0.8938799 | I44: 0.8923688 | J44: 0.8923509 | K44: 0.8942058 | L44: 0.8924763 | M44: 0.9077411 | N44: 0.8925128 | O44: 0.9029984 | P44: 0.8956165 | Q44: 0.8922286 | R44: 0.8979723 | S44: 0.8923578 | T44: 0.8923631 | U44: 0.9118719 | V44: 0.8985085 | W44: 0.8918724 | X44: 0.9582686 | Y44: 0.893101 | Z44: 0.9581053 | AA44: 2.0289788 | AB44: 1.6978428
A45: Odroid01 | B45: P3 | C45: 0.0192196 | D45: 0.0197952 | E45: 0.0187101 | F45: 0 | G45: 0.898833 | H45: 0.8933766 | I45: 0.8922365 | J45: 0.9070115 | K45: 0.8926239 | L45: 0.9012425 | M45: 0.9022455 | N45: 0.8927739 | O45: 0.9294534 | P45: 0.8922389 | Q45: 0.8922451 | R45: 0.8922825 | S45: 0.8924749 | T45: 0.8923738 | U45: 0.8944931 | V45: 0.9024763 | W45: 0.8920701 | X45: 0.9543965 | Y45: 0.8933308 | Z45: 0.9630177 | AA45: 2.0435865 | AB45: 1.6810935
A46: Odroid02 | B46: P4 | C46: 0.9036915 | D46: 0.9815161 | E46: 0.9775667 | F46: 0.9127996 | G46: 0 | H46: 0.0180106 | I46: 0.0379376 | J46: 0.0327773 | K46: 0.9098845 | L46: 0.997915 | M46: 0.938328 | N46: 1.0135162 | O46: 0.9823723 | P46: 0.9118774 | Q46: 0.921663 | R46: 0.9018013 | S46: 0.9400637 | T46: 0.9106174 | U46: 0.9439032 | V46: 0.9899602 | W46: 0.9352779 | X46: 0.9470289 | Y46: 0.893018 | Z46: 1.084409 | AA46: 1.8589091 | AB46: 1.5049629
A47: Odroid02 | B47: P5 | C47: 0.9010136 | D47: 0.9242816 | E47: 0.9892995 | F47: 0.9522028 | G47: 0.019052 | H47: 0 | I47: 0.0379672 | J47: 0.0329294 | K47: 0.9957898 | L47: 0.9900796 | M47: 0.9880183 | N47: 0.9334555 | O47: 0.9575551 | P47: 0.9656312 | Q47: 1.0315022 | R47: 0.9024239 | S47: 0.9101858 | T47: 0.9111667 | U47: 1.0001447 | V47: 0.9800961 | W47: 0.9136126 | X47: 1.0055506 | Y47: 0.9597137 | Z47: 1.0430458 | AA47: 1.7761703 | AB47: 1.5092912
A48: Odroid02 | B48: P6 | C48: 0.962652 | D48: 0.9091873 | E48: 0.9035957 | F48: 0.9018707 | G48: 0.0391059 | H48: 0.02795 | I48: 0 | J48: 0.0374429 | K48: 0.8938658 | L48: 0.9665136 | M48: 0.9145048 | N48: 1.0220425 | O48: 0.894393 | P48: 0.9525623 | Q48: 0.9582462 | R48: 0.9995348 | S48: 0.9443917 | T48: 0.9270256 | U48: 0.9003367 | V48: 0.9135089 | W48: 0.9118657 | X48: 0.9915271 | Y48: 0.8930116 | Z48: 0.9385972 | AA48: 1.9913497 | AB48: 1.5564752
A49: Odroid02 | B49: P7 | C49: 0.8942878 | D49: 0.9245324 | E49: 0.9320695 | F49: 0.935123 | G49: 0.0283983 | H49: 0.0184352 | I49: 0.0623515 | J49: 0 | K49: 0.9641492 | L49: 0.9182682 | M49: 0.9427369 | N49: 0.8934164 | O49: 0.9586647 | P49: 0.8996644 | Q49: 0.9057941 | R49: 0.9400609 | S49: 0.9910946 | T49: 0.9330196 | U49: 0.9675024 | V49: 0.9099798 | W49: 0.8931665 | X49: 1.0051043 | Y49: 0.9251184 | Z49: 1.0292897 | AA49: 1.7274432 | AB49: 1.4860003
A50: Odroid03 | B50: P8 | C50: 0.9201257 | D50: 0.9355972 | E50: 0.8946393 | F50: 0.8940504 | G50: 0.9993746 | H50: 0.9018064 | I50: 0.9188848 | J50: 0.9756641 | K50: 0 | L50: 0.0187235 | M50: 0.0182865 | N50: 0.0203726 | O50: 0.9793179 | P50: 0.9469459 | Q50: 0.9650702 | R50: 0.9146783 | S50: 0.9431615 | T50: 0.8980408 | U50: 0.9234416 | V50: 0.9701216 | W50: 0.9665649 | X50: 0.9658103 | Y50: 0.8939252 | Z50: 0.9785452 | AA50: 1.8519895 | AB50: 1.5394175
A51: Odroid03 | B51: P9 | C51: 0.9790754 | D51: 0.911268 | E51: 0.9288116 | F51: 0.9267631 | G51: 0.9450223 | H51: 1.0094316 | I51: 0.8952777 | J51: 0.9494166 | K51: 0.1554689 | L51: 0 | M51: 0.0281639 | N51: 0.0383174 | O51: 0.9432554 | P51: 0.8965132 | Q51: 0.894027 | R51: 0.894377 | S51: 0.9722643 | T51: 0.9438775 | U51: 0.9037633 | V51: 0.9449914 | W51: 0.9654138 | X51: 1.0137806 | Y51: 0.9445829 | Z51: 1.0550654 | AA51: 1.9567561 | AB51: 1.5441546
A52: Odroid03 | B52: P10 | C52: 0.9234989 | D52: 0.9196448 | E52: 0.9072697 | F52: 0.9944277 | G52: 0.9876318 | H52: 0.8953731 | I52: 1.0112433 | J52: 1.0177574 | K52: 0.2388968 | L52: 0.0387995 | M52: 0 | N52: 0.0181739 | O52: 0.9052734 | P52: 0.9550045 | Q52: 0.9692485 | R52: 0.9025476 | S52: 0.9001236 | T52: 0.9467678 | U52: 0.9602482 | V52: 0.8955097 | W52: 0.941385 | X52: 1.0267816 | Y52: 0.8940308 | Z52: 0.9455602 | AA52: 1.7900629 | AB52: 1.464905
A53: Odroid03 | B53: P11 | C53: 0.8946495 | D53: 0.8997653 | E53: 0.9163022 | F53: 0.9010382 | G53: 0.9385018 | H53: 0.9058933 | I53: 0.909658 | J53: 0.894912 | K53: 0.0492599 | L53: 0.0206985 | M53: 0.0200646 | N53: 0 | O53: 1.00773 | P53: 0.9218211 | Q53: 1.041858 | R53: 0.917871 | S53: 0.8937676 | T53: 1.054074 | U53: 1.0138581 | V53: 1.0382512 | W53: 0.9099927 | X53: 1.1176786 | Y53: 0.9024413 | Z53: 1.047621 | AA53: 1.8130622 | AB53: 1.5422523
... A67: Raspi02 | B67: P25 | C67: 1.0910037 | D67: 1.0637901 | E67: 1.0601933 | F67: 1.0607562 | G67: 1.0910316 | H67: 1.1032305 | I67: 1.0825958 | J67: 1.1148694 | K67: 1.1022797 | L67: 1.1305721 | M67: 1.0908496 | N67: 1.0942166 | O67: 1.0917757 | P67: 1.0931916 | Q67: 1.0886075 | R67: 1.1135752 | S67: 1.0856416 | T67: 1.0928056 | U67: 1.0963943 | V67: 1.1168931 | W67: 1.0645931 | X67: 1.1876431 | Y67: 1.067668 | Z67: 1.1896439 | AA67: 1.736613 | AB67: 0

Sheet RAW One core per device
A1: Node name odroid01
A2: P0 comp times | B2: 0.71772 | C2: 0.5540404 | D2: 0.7353783 | E2: 0.7354515
A3: P0 send to times | B3: 0 | C3: 0.8780336 | D3: 0.8803761 | E3: 0.8815136 | F3: 0.8815534 | G3: 0.8893278 | H3: 0.8871367
A4: P0 recv from times | B4: 0 | C4: 0.8922203 | D4: 0.8926995 | E4: 0.892487 | F4: 0.8927965 | G4: 0.8919461 | H4: 0.8926008
A5: Node name odroid02 | B5: =AVERAGE(B3,B4) -> 0 | C5: =AVERAGE(C3,C4) -> 0.88512695 | D5: =AVERAGE(D3,D4) -> 0.8865378 | E5: =AVERAGE(E3,E4) -> 0.8870003 | F5: =AVERAGE(F3,F4) -> 0.88717495 | G5: =AVERAGE(G3,G4) -> 0.89063695 | H5: =AVERAGE(H3,H4) -> 0.88986875
A6: P1 comp times | B6: 0.7346902 | C6: 0.5542085 | D6: 0.7351716 | E6: 0.7352653
A7: P1 send to times | B7: 0.875109 | C7: 0 | D7: 0.8820665 | E7: 0.8818176 | F7: 0.88257 | G7: 0.8779378 | H7: 0.8778107
A8: P1 recv from times | B8: 0.893573 | C8: 0 | D8: 0.8943555 | E8: 0.8946245 | F8: 0.8942463 | G8: 0.8932815 | H8: 0.8934913
A9: Node name odroid03 | B9: =AVERAGE(B7,B8) -> 0.884341 | C9: =AVERAGE(C7,C8) -> 0 | D9: =AVERAGE(D7,D8) -> 0.888211 | E9: =AVERAGE(E7,E8) -> 0.88822105 | F9: =AVERAGE(F7,F8) -> 0.88840815 | G9: =AVERAGE(G7,G8) -> 0.88560965 | H9: =AVERAGE(H7,H8) -> 0.885651
A10: P2 comp times | B10: 0.7351234 | C10: 0.5539336 | D10: 0.7356129 | E10: 0.7358246
A11: P2 send to times | B11: 0.8779681 | C11: 0.8822885 | D11: 0 | E11: 0.8825061 | F11: 0.8823712 | G11: 0.8802674 | H11: 0.8787584
A12: P2 recv from times | B12: 0.8954732 | C12: 0.8941002 | D12: 0 | E12: 0.8942506 | F12: 0.89498 | G12: 0.8930421 | H12: 0.8936548
A13: Node name odroid04 | B13: =AVERAGE(B11,B12) -> 0.88672065 | C13: =AVERAGE(C11,C12) -> 0.88819435 | D13: =AVERAGE(D11,D12) -> 0 | E13: =AVERAGE(E11,E12) -> 0.88837835 | F13: =AVERAGE(F11,F12) -> 0.8886756 | G13: =AVERAGE(G11,G12) -> 0.88665475 | H13: =AVERAGE(H11,H12) -> 0.8862066
A14: P3 comp times | B14: 0.6795611 | C14: 0.5588586 | D14: 0.7356608 | E14: 0.7356374
A15: P3 send to times | B15: 0.8756342 | C15: 0.8823154 | D15: 0.8826075 | E15: 0 | F15: 0.882185 | G15: 0.8766406 | H15: 0.8751173
A16: P3 recv from times | B16: 0.8938634 | C16: 0.894366 | D16: 0.8944697 | E16: 0 | F16: 0.8942242 | G16: 0.8933678 | H16: 0.8932579
A17: Node name odroid05 | B17: =AVERAGE(B15,B16) -> 0.8847488 | C17: =AVERAGE(C15,C16) -> 0.8883407 | D17: =AVERAGE(D15,D16) -> 0.8885386 | E17: =AVERAGE(E15,E16) -> 0 | F17: =AVERAGE(F15,F16) -> 0.8882046 | G17: =AVERAGE(G15,G16) -> 0.8850042 | H17: =AVERAGE(H15,H16) -> 0.8841876
A18: P4 comp times | B18: 0.7337229 | C18: 0.5491896 | D18: 0.7355223 | E18: 0.7364063
A19: P4 send to times | B19: 0.8805304 | C19: 0.882355 | D19: 0.8826873 | E19: 0.8825712 | F19: 0 | G19: 0.8760483 | H19: 0.8807709
A20: P4 recv from times | B20: 0.893501 | C20: 0.8949852 | D20: 0.8959944 | E20: 0.8947935 | F20: 0 | G20: 0.8931782 | H20: 0.8934879
A21: Node name cubie01 | B21: =AVERAGE(B19,B20) -> 0.8870157 | C21: =AVERAGE(C19,C20) -> 0.8886701 | D21: =AVERAGE(D19,D20) -> 0.88934085 | E21: =AVERAGE(E19,E20) -> 0.88868235 | F21: =AVERAGE(F19,F20) -> 0 | G21: =AVERAGE(G19,G20) -> 0.88461325 | H21: =AVERAGE(H19,H20) -> 0.8871294
A22: P5 comp times | B22: 1.8010941 | C22: 1.59076 | D22: 1.788518 | E22: 1.7885957
A23: P5 send to times | B23: 0.8777657 | C23: 0.8824697 | D23: 0.8843923 | E23: 0.8797972 | F23: 0.8845217 | G23: 0 | H23: 0.8847623
A24: P5 recv from times | B24: 0.8942513 | C24: 0.8920596 | D24: 0.8924661 | E24: 0.8925102 | F24: 0.8922524 | G24: 0 | H24: 0.894088
A25: Node name cubie02 | B25: =AVERAGE(B23,B24) -> 0.8860085 | C25: =AVERAGE(C23,C24) -> 0.88726465 | D25: =AVERAGE(D23,D24) -> 0.8884292 | E25: =AVERAGE(E23,E24) -> 0.8861537 | F25: =AVERAGE(F23,F24) -> 0.88838705 | G25: =AVERAGE(G23,G24) -> 0 | H25: =AVERAGE(H23,H24) -> 0.88942515
A26: P6 comp times | B26: 1.8004255 | C26: 1.5899639 | D26: 1.7885997 | E26: 1.7885766
A27: P6 send to times | B27: 0.8809471 | C27: 0.8839014 | D27: 0.8841872 | E27: 0.8830063 | F27: 0.8828616 | G27: 0.883316 | H27: 0
A28: P6 recv from times | B28: 0.9013517 | C28: 0.8922207 | D28: 0.8924513 | E28: 0.8924046 | F28: 0.8953707 | G28: 0.892875 | H28: 0
B29: =AVERAGE(B27,B28) -> 0.8911494 | C29: =AVERAGE(C27,C28) -> 0.88806105 | D29: =AVERAGE(D27,D28) -> 0.88831925 | E29: =AVERAGE(E27,E28) -> 0.88770545 | F29: =AVERAGE(F27,F28) -> 0.88911615 | G29: =AVERAGE(G27,G28) -> 0.8880955 | H29: =AVERAGE(H27,H28) -> 0

Sheet RAW All cores per device
C1: P1 | D1: P2 | E1: P3 | F1: P4 | G1: P5 | H1: P6 | I1: P7 | J1: P8 | K1: P9 | L1: P10 | M1: P11 | N1: P12 | O1: P13 | P1: P14 | Q1: P15 | R1: P16 | S1: P17 | T1: P18 | U1: P19 | V1: P20 | W1: P21 | X1: P22 | Y1: P23 | Z1: P24
B2: Node name odroid01
B3: P0 comp times | C3: 0.7382963 | D3: 0.555614 | E3: 0.7363863 | F3: 0.7361596
B4: P0 send to times | C4: 0 | D4: 0.8912199 | E4: 0.8765662 | F4: 0.8801889 | G4: 0.8795443 | H4: 0.8760173 | I4: 0.981375 | J4: 0.0186582 | K4: 0.9669995 | L4: 0.888149 | M4: 0.8825378 | N4: 0.8802631 | O4: 1.0144064 | P4: 1.0379646 | Q4: 0.01841 | R4: 0.9122968 | S4: 0.9224546 | T4: 0.8823981 | U4: 0.882395 | V4: 0.9555602 | W4: 1.0331392 | X4: 0.0188882 | Y4: 0.9700627 | Z4: 0.8796251
B5: P0 recv from times | C5: 0 | D5: 0.8923988 | E5: 0.8922257 | F5: 0.8922467 | G5: 0.8918381 | H5: 1.0137613 | I5: 0.8926027 | J5: 0.0181851 | K5: 0.8958788 | L5: 0.9040861 | M5: 0.8917544 | N5: 0.8963575 | O5: 1.0058975 | P5: 0.9371381 | Q5: 0.0180104 | R5: 0.8919044 | S5: 0.8923755 | T5: 0.8918862 | U5: 0.8919127 | V5: 0.8921485 | W5: 0.9494476 | X5: 0.0177696 | Y5: 0.9034951 | Z5: 0.8984399
B6: Node name odroid02
B7: P1 comp times | C7: 0.8048089 | D7: 0.6854336 | E7: 1.1257956 | F7: 0.8855114
B8: P1 send to times | C8: 0.8829825 | D8: 0 | E8: 0.9827137 | F8: 0.8795066 | G8: 0.8816216 | H8: 1.0203795 | I8: 0.8818412 | J8: 0.8823662 | K8: 0.0188491 | L8: 0.9160836 | M8: 0.9026108 | N8: 0.8820705 | O8: 1.0238538 | P8: 1.0471017 | Q8: 0.8774562 | R8: 0.0190468 | S8: 1.0048656 | T8: 0.8824506 | U8: 0.8833897 | V8: 0.9553852 | W8: 1.1554513 | X8: 0.8895409 | Y8: 0.0382831 | Z8: 0.8891573
B9: P1 recv from times | C9: 0.8932242 | D9: 0 | E9: 0.9223351 | F9: 0.9567947 | G9: 0.8936696 | H9: 1.0271509 | I9: 0.9580522 | J9: 0.9955366 | K9: 0.0372243 | L9: 0.9574854 | M9: 0.9560337 | N9: 0.916765 | O9: 0.9555254 | P9: 1.0900707 | Q9: 0.8975718 | R9: 0.0177181 | S9: 0.947139 | T9: 0.9508564 | U9: 0.8937604 | V9: 0.9215596 | W9: 1.1031845 | X9: 0.9070597 | Y9: 0.0185149 | Z9: 0.9929461
B10: Node name odroid03
B11: P2 comp times | C11: 0.8325372 | D11: 0.7277727 | E11: 0.7956429 | F11: 1.080889
B12: P2 send to times | C12: 0.8791552 | D12: 0.9176507 | E12: 0 | F12: 0.9227242 | G12: 0.9078526 | H12: 0.9180233 | I12: 0.8753512 | J12: 0.8784523 | K12: 0.9176292 | L12: 0.030189 | M12: 0.8831844 | N12: 0.8825083 | O12: 1.0287967 | P12: 1.0077519 | Q12: 0.8862886 | R12: 0.8953693 | S12: 0.0389874 | T12: 0.8903739 | U12: 0.8862312 | V12: 1.0096087 | W12: 1.1026773 | X12: 0.8868771 | Y12: 0.9689164 | Z12: 0.0284009
B13: P2 recv from times | C13: 0.8936174 | D13: 1.0017216 | E13: 0 | F13: 0.9443402 | G13: 0.9054005 | H13: 0.9502456 | I13: 0.8931115 | J13: 0.9169326 | K13: 0.9565735 | L13: 0.0185411 | M13: 0.8933911 | N13: 0.9666471 | O13: 0.9859667 | P13: 0.9636407 | Q13: 0.8933606 | R13: 0.9325161 | S13: 0.034554 | T13: 0.893306 | U13: 0.9091527 | V13: 0.9268489 | W13: 1.0401087 | X13: 0.9038386 | Y13: 0.9180484 | Z13: 0.0582526
B14: Node name odroid04
B15: P3 comp times | C15: 0.6796339 | D15: 0.5584648 | E15: 0.7357173 | F15: 0.7361138
B16: P3 send to times | C16: 0.879921 | D16: 0.9395027 | E16: 0.9293122 | F16: 0 | G16: 0.8813756 | H16: 1.014199 | I16: 0.8753529 | J16: 0.8762412 | K16: 0.9585867 | L16: 0.9643421 | M16: 0.0188937 | N16: 0.8840117 | O16: 1.0555408 | P16: 1.0878096 | Q16: 0.8765996 | R16: 0.9843736 | S16: 0.8820238 | T16: 0.0191741 | U16: 0.8834119 | V16: 0.8767247 | W16: 1.0574412 | X16: 0.8762379 | Y16: 0.9670925 | Z16: 0.9367471
B17: P3 recv from times | C17: 0.8964708 | D17: 0.8959794 | E17: 0.9262631 | F17: 0 | G17: 0.8982296 | H17: 0.9439116 | I17: 0.892987 | J17: 0.8936579 | K17: 0.8942075 | L17: 0.8943975 | M17: 0.0181863 | N17: 0.8936124 | O17: 0.9414856 | P17: 0.939986 | Q17: 0.8934908 | R17: 0.8942251 | S17: 0.9225066 | T17: 0.0178146 | U17: 0.8938739 | V17: 0.8959219 | W17: 0.9487944 | X17: 0.8937521 | Y17: 0.903363 | Z17: 0.8949864
B18: Node name odroid05
B19: P4 comp times | C19: 0.6819882 | D19: 0.5584373 | E19: 0.7355192 | F19: 0.735532
B20: P4 send to times | C20: 0.8751047 | D20: 0.8815215 | E20: 0.8927917 | F20: 0.8773792 | G20: 0 | H20: 1.0711834 | I20: 0.8752279 | J20: 0.8763788 | K20: 0.9338944 | L20: 0.9200635 | M20: 0.8827794 | N20: 0.0186813 | O20: 1.003602 | P20: 0.9980478 | Q20: 0.8769836 | R20: 0.9623256 | S20: 0.9619265 | T20: 0.88289 | U20: 0.0184944 | V20: 0.8847327 | W20: 0.9984415 | X20: 0.8767371 | Y20: 0.9477761 | Z20: 0.9160826
B21: P4 recv from times | C21: 0.8931222 | D21: 0.8962202 | E21: 0.9164822 | F21: 0.8936384 | G21: 0 | H21: 0.9370568 | I21: 0.8933585 | J21: 0.8932576 | K21: 0.8967593 | L21: 0.9012167 | M21: 0.8937774 | N21: 0.01858 | O21: 0.9784026 | P21: 0.9627237 | Q21: 0.8930109 | R21: 0.8941145 | S21: 0.8968856 | T21: 0.8943751 | U21: 0.0189502 | V21: 0.8928363 | W21: 0.9343612 | X21: 0.8933461 | Y21: 0.8993478 | Z21: 0.896719
B22: Node name cubie01
B23: P5 comp times | C23: 3.6219628 | D23: 3.1862373 | E23: 2.8632758 | F23: 2.7685792
B24: P5 send to times | C24: 1.0020514 | D24: 1.0229814 | E24: 0.9458458 | F24: 0.9399304 | G24: 0.9346509 | H24: 0 | I24: 1.0000927 | J24: 1.0419855 | K24: 1.0695963 | L24: 1.0764296 | M24: 0.9301817 | N24: 0.9506917 | O24: 1.0001972 | P24: 1.0701897 | Q24: 0.9400609 | R24: 0.9903321 | S24: 1.0354798 | T24: 0.9714158 | U24: 0.990206 | V24: 0.0899642 | W24: 1.0273981 | X24: 0.9303579 | Y24: 1.0401001 | Z24: 1.0198755
B25: P5 recv from times | C25: 0.8923516 | D25: 1.0254176 | E25: 0.9364579 | F25: 1.0216405 | G25: 1.0774291 | H25: 0 | I25: 1.1612384 | J25: 1.10303 | K25: 0.9977429 | L25: 1.0663557 | M25: 1.0137658 | N25: 1.1416855 | O25: 0.9765401 | P25: 1.2064557 | Q25: 1.070451 | R25: 1.1199172 | S25: 1.0009246 | T25: 1.0601492 | U25: 1.019367 | V25: 0.0656567 | W25: 1.1104116 | X25: 1.0192804 | Y25: 1.1640935 | Z25: 1.0289836
B26: Node name cubie02
B27: P6 comp times | C27: 3.4532492 | D27: 3.2484446 | E27: 2.7866964 | F27: 2.9172852
B28: P6 send to times | C28: 0.8828537 | D28: 0.9485466 | E28: 0.8823922 | F28: 0.8823779 | G28: 0.8810248 | H28: 1.1485407 | I28: 0 | J28: 0.8834178 | K28: 0.9137449 | L28: 0.9341309 | M28: 0.8840327 | N28: 0.8811419 | O28: 1.0096474 | P28: 0.0821643 | Q28: 0.8795002 | R28: 0.9459529 | S28: 0.8829336 | T28: 0.8836432 | U28: 0.8837273 | V28: 0.8862247 | W28: 0.0786808 | X28: 0.8795221 | Y28: 0.9607215 | Z28: 0.8943882
B29: P6 recv from times | C29: 0.9901016 | D29: 0.8938303 | E29: 0.8921728 | F29: 0.8923304 | G29: 0.8922086 | H29: 1.0054934 | I29: 0 | J29: 0.89165 | K29: 0.8974712 | L29: 0.8920934 | M29: 0.8922994 | N29: 0.8921473 | O29: 1.0089915 | P29: 0.0737422 | Q29: 0.8916457 | R29: 0.9004159 | S29: 0.8973038 | T29: 0.8923018 | U29: 0.8921621 | V29: 0.8921461 | W29: 0.0712354 | X29: 0.8919668 | Y29: 0.8949542 | Z29: 0.894443
B30: Node name odroid01
B31: P7 comp times | C31: 0.7461092 | D31: 0.5556548 | E31: 0.736021 | F31: 0.7361999
